<?xml version="1.0" encoding="utf-8"?>
<!-- This URDF was automatically created by SolidWorks to URDF Exporter! Originally created by Stephen Brawner (brawner@gmail.com) 
     Commit Version: 1.5.1-0-g916b5db  Build Version: 1.5.7152.31018
     For more information, please see http://wiki.ros.org/sw_urdf_exporter -->
<robot
  name="model">
  <link
    name="base_link">
    <inertial>
      <origin
        xyz="-0.24468 -0.032762 0.15137"
        rpy="0 0 0" />
      <mass
        value="0.41067" />
      <inertia
        ixx="1"
        ixy="2.8611E-20"
        ixz="-2.4187E-20"
        iyy="1"
        iyz="2.3129E-20"
        izz="1" />
    </inertial>
    <visual>
      <origin
        xyz="0 0 0"
        rpy="0 0 0" />
      <geometry>
        <mesh
          filename="package://model/meshes/base_link.STL" />
      </geometry>
      <material
        name="">
        <color
          rgba="255 0 0 255" />
      </material>
    </visual>
    <collision>
      <origin
        xyz="0 0 0"
        rpy="0 0 0" />
      <geometry>
        <mesh
          filename="package://model/meshes/base_link.STL" />
      </geometry>
    </collision>
  </link>
  <gazebo reference="base_link">
    <material>Gazebo/Orange</material>
  </gazebo>
  <link
    name="wheelLF">
    <inertial>
      <origin
        xyz="-5.5511E-17 -6.9389E-18 0.01"
        rpy="0 0 0" />
      <mass
        value="0.073114" />
      <inertia
        ixx="2.4579E-05"
        ixy="-1.4998E-40"
        ixz="-8.8233E-24"
        iyy="2.4579E-05"
        iyz="-3.3694E-38"
        izz="4.4495E-05" />
    </inertial>
    <visual>
      <origin
        xyz="0 0 0"
        rpy="0 0 0" />
      <geometry>
        <mesh
          filename="package://model/meshes/wheelLF.STL" />
      </geometry>
      <material
        name="">
        <color
          rgba="0.29804 0.29804 0.29804 1" />
      </material>
    </visual>
    <collision>
      <origin
        xyz="0 0 0"
        rpy="0 0 0" />
      <geometry>
        <mesh
          filename="package://model/meshes/wheelLF.STL" />
      </geometry>
    </collision>
  </link>
  <gazebo reference="wheelLF">
    <material>Gazebo/Black</material>
  </gazebo>
  <joint
    name="jointLF"
    type="continuous">
    <origin
      xyz="-0.3229 -0.22837 -0.032762"
      rpy="1.5708 0 0" />
    <parent
      link="base_link" />
    <child
      link="wheelLF" />
    <axis
      xyz="0 0 1" />
  </joint>
  <link
    name="wheelRF">
    <inertial>
      <origin
        xyz="5.5511E-17 0 0.01"
        rpy="0 0 0" />
      <mass
        value="0.073114" />
      <inertia
        ixx="2.4579E-05"
        ixy="-1.4998E-40"
        ixz="2.7352E-22"
        iyy="2.4579E-05"
        iyz="-3.3694E-38"
        izz="4.4495E-05" />
    </inertial>
    <visual>
      <origin
        xyz="0 0 0"
        rpy="0 0 0" />
      <geometry>
        <mesh
          filename="package://model/meshes/wheelRF.STL" />
      </geometry>
      <material
        name="">
        <color
          rgba="0.29804 0.29804 0.29804 1" />
      </material>
    </visual>
    <collision>
      <origin
        xyz="0 0 0"
        rpy="0 0 0" />
      <geometry>
        <mesh
          filename="package://model/meshes/wheelRF.STL" />
      </geometry>
    </collision>
  </link>
  <gazebo reference="wheelRF">
    <material>Gazebo/Black</material>
  </gazebo>
  <joint
    name="jointRF"
    type="continuous">
    <origin
      xyz="-0.3229 -0.058371 -0.032762"
      rpy="1.5708 0 0" />
    <parent
      link="base_link" />
    <child
      link="wheelRF" />
    <axis
      xyz="0 0 1" />
  </joint>
  <link
    name="wheelLB">
    <inertial>
      <origin
        xyz="0 0 0.01"
        rpy="0 0 0" />
      <mass
        value="0.073114" />
      <inertia
        ixx="2.4579E-05"
        ixy="4.2352E-22"
        ixz="9.5316E-22"
        iyy="2.4579E-05"
        iyz="1.6908E-22"
        izz="4.4495E-05" />
    </inertial>
    <visual>
      <origin
        xyz="0 0 0"
        rpy="0 0 0" />
      <geometry>
        <mesh
          filename="package://model/meshes/wheelLB.STL" />
      </geometry>
      <material
        name="">
        <color
          rgba="0.29804 0.29804 0.29804 1" />
      </material>
    </visual>
    <collision>
      <origin
        xyz="0 0 0"
        rpy="0 0 0" />
      <geometry>
        <mesh
          filename="package://model/meshes/wheelLB.STL" />
      </geometry>
    </collision>
  </link>
  <gazebo reference="wheelLB">
    <material>Gazebo/Black</material>
  </gazebo>
  <joint
    name="jointLB"
    type="continuous">
    <origin
      xyz="-0.16645 -0.22837 -0.032762"
      rpy="1.5708 0.28207 0" />
    <parent
      link="base_link" />
    <child
      link="wheelLB" />
    <axis
      xyz="0 0 1" />
  </joint>
  <link
    name="wheelRB">
    <inertial>
      <origin
        xyz="-3.4694E-18 5.5511E-17 0.01"
        rpy="0 0 0" />
      <mass
        value="0.073114" />
      <inertia
        ixx="2.4579E-05"
        ixy="-2.1176E-22"
        ixz="4.6884E-22"
        iyy="2.4579E-05"
        iyz="-1.0642E-24"
        izz="4.4495E-05" />
    </inertial>
    <visual>
      <origin
        xyz="0 0 0"
        rpy="0 0 0" />
      <geometry>
        <mesh
          filename="package://model/meshes/wheelRB.STL" />
      </geometry>
      <material
        name="">
        <color
          rgba="0.29804 0.29804 0.29804 1" />
      </material>
    </visual>
    <collision>
      <origin
        xyz="0 0 0"
        rpy="0 0 0" />
      <geometry>
        <mesh
          filename="package://model/meshes/wheelRB.STL" />
      </geometry>
    </collision>
  </link>
  <gazebo reference="wheelRB">
    <material>Gazebo/Black</material>
  </gazebo>
  <joint
    name="jointRB"
    type="continuous">
    <origin
      xyz="-0.16645 -0.054371 -0.032762"
      rpy="1.5708 1.5064 0" />
    <parent
      link="base_link" />
    <child
      link="wheelRB" />
    <axis
      xyz="0 0 1" />
  </joint>
  <link
    name="lidar">
    <inertial>
      <origin
        xyz="0 0 0"
        rpy="0 0 0" />
      <mass
        value="0" />
      <inertia
        ixx="0"
        ixy="0"
        ixz="0"
        iyy="0"
        iyz="0"
        izz="0" />
    </inertial>
    <visual>
      <origin
        xyz="0 0 0"
        rpy="0 0 0" />
      <geometry>
        <mesh
          filename="package://model/meshes/lidar.STL" />
      </geometry>
      <material
        name="">
        <color
          rgba="0 0 0 255" />
      </material>
    </visual>
    <collision>
      <origin
        xyz="0 0 0"
        rpy="0 0 0" />
      <geometry>
        <mesh
          filename="package://model/meshes/lidar.STL" />
      </geometry>
    </collision>
  </link>
  <gazebo reference="lidar">
    <material>Gazebo/Black</material>
  </gazebo>
  <joint
    name="lidarjoint"
    type="fixed">
    <origin
      xyz="-0.29589 -0.15066 0.011838"
      rpy="0 3.14 0" />
    <parent
      link="base_link" />
    <child
      link="lidar" />h
    <axis
      xyz="0 0 0" />
  </joint>
    <gazebo reference="lidar">
    <sensor type="ray" name="head_hokuyo_sensor">
      <pose> 0 0 0 0 0 0 </pose>
      <visualize>true</visualize>
      <update_rate>40</update_rate>
      <ray>
        <scan>
          <horizontal>
            <samples>720</samples>
            <resolution>1</resolution>
            <min_angle>-1.57</min_angle>
            <max_angle>1.57</max_angle>
          </horizontal>
        </scan>
        <range>
          <min>0.10</min>
          <max>30.0</max>
          <resolution>0.01</resolution>
        </range>
        <noise>
          <type>gaussian</type>
          <!-- Noise parameters based on published spec for Hokuyo laser
               achieving "+-30mm" accuracy at range < 10m.  A mean of 0.0m and
               stddev of 0.01m will put 99.7% of samples within 0.03m of the true
               reading. -->
          <mean>0.0</mean>
          <stddev>0.01</stddev>
        </noise>
      </ray>
      <plugin name="gazebo_ros_head_hokuyo_controller" filename="libgazebo_ros_laser.so">
        <topicName>/rrbot/laser/scan</topicName>
	<robotNamespace>/</robotNamespace>
        <frameName>lidar</frameName>

      </plugin>
    </sensor>
  </gazebo>
 <gazebo>
  <plugin name="skid_steer_drive_controller" filename="libgazebo_ros_skid_steer_drive.so">
    <updateRate>100.0</updateRate>
    <leftFrontJoint>jointLF</leftFrontJoint>
    <rightFrontJoint>jointRF</rightFrontJoint>
    <leftRearJoint>jointLB</leftRearJoint>
    <rightRearJoint>jointRB</rightRearJoint>
    <wheelSeparation>0.4</wheelSeparation>
    <wheelDiameter>0.25</wheelDiameter>
    <robotBaseFrame>base_link</robotBaseFrame>
    <torque>5</torque>
    <commandTopic>turtle1/cmd_vel</commandTopic>
    <broadcastTF>true</broadcastTF>
    <odometryTopic>odom</odometryTopic>

    <!-- Odometry frame, defaults to `odom` -->
    <odometryFrame>odom</odometryFrame>

    <!-- Robot frame to calculate odometry from, defaults to `base_footprint` -->
    <robotBaseFrame>base_link</robotBaseFrame>

    <!-- Odometry source, 0 for ENCODER, 1 for WORLD, defaults to WORLD -->
    <odometrySource>1</odometrySource>

    <!-- Set to true to publish transforms for the wheel links, defaults to false -->
    <publishWheelTF>true</publishWheelTF>

    <!-- Set to true to publish transforms for the odometry, defaults to true -->
    <publishOdom>true</publishOdom>

    <!-- Set to true to publish sensor_msgs/JointState on /joint_states for the wheel joints, defaults to false -->
    <publishWheelJointState>true</publishWheelJointState>

  </plugin>
</gazebo>
</robot>
